WARNING 2025-08-24 09:12:07,216 log Not Found: /zhuye/ssss/
WARNING 2025-08-24 09:12:11,292 log Not Found: /chat/ssss/
WARNING 2025-08-24 09:52:29,288 log Not Found: /chat/chat/group_selector/
WARNING 2025-08-24 09:57:54,735 log Not Found: /chat/chat/room_list/
ERROR 2025-08-24 10:18:18,122 log Internal Server Error: /chat/chat/room_list/
Traceback (most recent call last):
  File "C:\Users\Administrator\dl\.venv\Lib\site-packages\django\template\base.py", line 510, in parse
    compile_func = self.tags[command]
                   ~~~~~~~~~^^^^^^^^^
KeyError: 'endfor'

During handling of the above exception, another exception occurred:

Traceback (most recent call last):
  File "C:\Users\Administrator\dl\.venv\Lib\site-packages\asgiref\sync.py", line 489, in thread_handler
    raise exc_info[1]
  File "C:\Users\Administrator\dl\.venv\Lib\site-packages\django\core\handlers\exception.py", line 42, in inner
    response = await get_response(request)
               ^^^^^^^^^^^^^^^^^^^^^^^^^^^
  File "C:\Users\Administrator\dl\.venv\Lib\site-packages\asgiref\sync.py", line 489, in thread_handler
    raise exc_info[1]
  File "C:\Users\Administrator\dl\.venv\Lib\site-packages\django\core\handlers\base.py", line 253, in _get_response_async
    response = await wrapped_callback(
               ^^^^^^^^^^^^^^^^^^^^^^^
        request, *callback_args, **callback_kwargs
        ^^^^^^^^^^^^^^^^^^^^^^^^^^^^^^^^^^^^^^^^^^
    )
    ^
  File "C:\Users\Administrator\dl\.venv\Lib\site-packages\asgiref\sync.py", line 439, in __call__
    ret = await asyncio.shield(exec_coro)
          ^^^^^^^^^^^^^^^^^^^^^^^^^^^^^^^
  File "C:\python\Lib\concurrent\futures\thread.py", line 59, in run
    result = self.fn(*self.args, **self.kwargs)
  File "C:\Users\Administrator\dl\.venv\Lib\site-packages\asgiref\sync.py", line 493, in thread_handler
    return func(*args, **kwargs)
  File "C:\Users\Administrator\dl\gerenzhuye\chat\views.py", line 26, in group_selector
    return render(request, 'chat/group_selector.html', {'chat_groups':chat_groups})
  File "C:\Users\Administrator\dl\.venv\Lib\site-packages\django\shortcuts.py", line 25, in render
    content = loader.render_to_string(template_name, context, request, using=using)
  File "C:\Users\Administrator\dl\.venv\Lib\site-packages\django\template\loader.py", line 61, in render_to_string
    template = get_template(template_name, using=using)
  File "C:\Users\Administrator\dl\.venv\Lib\site-packages\django\template\loader.py", line 15, in get_template
    return engine.get_template(template_name)
           ~~~~~~~~~~~~~~~~~~~^^^^^^^^^^^^^^^
  File "C:\Users\Administrator\dl\.venv\Lib\site-packages\django\template\backends\django.py", line 79, in get_template
    return Template(self.engine.get_template(template_name), self)
                    ~~~~~~~~~~~~~~~~~~~~~~~~^^^^^^^^^^^^^^^
  File "C:\Users\Administrator\dl\.venv\Lib\site-packages\django\template\engine.py", line 177, in get_template
    template, origin = self.find_template(template_name)
                       ~~~~~~~~~~~~~~~~~~^^^^^^^^^^^^^^^
  File "C:\Users\Administrator\dl\.venv\Lib\site-packages\django\template\engine.py", line 159, in find_template
    template = loader.get_template(name, skip=skip)
  File "C:\Users\Administrator\dl\.venv\Lib\site-packages\django\template\loaders\cached.py", line 57, in get_template
    template = super().get_template(template_name, skip)
  File "C:\Users\Administrator\dl\.venv\Lib\site-packages\django\template\loaders\base.py", line 28, in get_template
    return Template(
        contents,
    ...<2 lines>...
        self.engine,
    )
  File "C:\Users\Administrator\dl\.venv\Lib\site-packages\django\template\base.py", line 154, in __init__
    self.nodelist = self.compile_nodelist()
                    ~~~~~~~~~~~~~~~~~~~~~^^
  File "C:\Users\Administrator\dl\.venv\Lib\site-packages\django\template\base.py", line 196, in compile_nodelist
    nodelist = parser.parse()
  File "C:\Users\Administrator\dl\.venv\Lib\site-packages\django\template\base.py", line 518, in parse
    raise self.error(token, e)
  File "C:\Users\Administrator\dl\.venv\Lib\site-packages\django\template\base.py", line 516, in parse
    compiled_result = compile_func(self, token)
  File "C:\Users\Administrator\dl\.venv\Lib\site-packages\django\template\loader_tags.py", line 299, in do_extends
    nodelist = parser.parse()
  File "C:\Users\Administrator\dl\.venv\Lib\site-packages\django\template\base.py", line 518, in parse
    raise self.error(token, e)
  File "C:\Users\Administrator\dl\.venv\Lib\site-packages\django\template\base.py", line 516, in parse
    compiled_result = compile_func(self, token)
  File "C:\Users\Administrator\dl\.venv\Lib\site-packages\django\template\loader_tags.py", line 234, in do_block
    nodelist = parser.parse(("endblock",))
  File "C:\Users\Administrator\dl\.venv\Lib\site-packages\django\template\base.py", line 512, in parse
    self.invalid_block_tag(token, command, parse_until)
    ~~~~~~~~~~~~~~~~~~~~~~^^^^^^^^^^^^^^^^^^^^^^^^^^^^^
  File "C:\Users\Administrator\dl\.venv\Lib\site-packages\django\template\base.py", line 567, in invalid_block_tag
    raise self.error(
    ...<8 lines>...
    )
django.template.exceptions.TemplateSyntaxError: Invalid block tag on line 22: 'endfor', expected 'endblock'. Did you forget to register or load this tag?
ERROR 2025-08-24 10:34:00,951 log Internal Server Error: /chat/chat/room_list/
Traceback (most recent call last):
  File "C:\Users\Administrator\dl\.venv\Lib\site-packages\asgiref\sync.py", line 489, in thread_handler
    raise exc_info[1]
  File "C:\Users\Administrator\dl\.venv\Lib\site-packages\django\core\handlers\exception.py", line 42, in inner
    response = await get_response(request)
               ^^^^^^^^^^^^^^^^^^^^^^^^^^^
  File "C:\Users\Administrator\dl\.venv\Lib\site-packages\asgiref\sync.py", line 489, in thread_handler
    raise exc_info[1]
  File "C:\Users\Administrator\dl\.venv\Lib\site-packages\django\core\handlers\base.py", line 253, in _get_response_async
    response = await wrapped_callback(
               ^^^^^^^^^^^^^^^^^^^^^^^
        request, *callback_args, **callback_kwargs
        ^^^^^^^^^^^^^^^^^^^^^^^^^^^^^^^^^^^^^^^^^^
    )
    ^
  File "C:\Users\Administrator\dl\.venv\Lib\site-packages\asgiref\sync.py", line 439, in __call__
    ret = await asyncio.shield(exec_coro)
          ^^^^^^^^^^^^^^^^^^^^^^^^^^^^^^^
  File "C:\python\Lib\concurrent\futures\thread.py", line 59, in run
    result = self.fn(*self.args, **self.kwargs)
  File "C:\Users\Administrator\dl\.venv\Lib\site-packages\asgiref\sync.py", line 493, in thread_handler
    return func(*args, **kwargs)
  File "C:\Users\Administrator\dl\.venv\Lib\site-packages\django\views\generic\base.py", line 105, in view
    return self.dispatch(request, *args, **kwargs)
           ~~~~~~~~~~~~~^^^^^^^^^^^^^^^^^^^^^^^^^^
  File "C:\Users\Administrator\dl\.venv\Lib\site-packages\django\views\generic\base.py", line 144, in dispatch
    return handler(request, *args, **kwargs)
  File "C:\Users\Administrator\dl\.venv\Lib\site-packages\django\views\generic\list.py", line 158, in get
    self.object_list = self.get_queryset()
                       ~~~~~~~~~~~~~~~~~^^
  File "C:\Users\Administrator\dl\gerenzhuye\chat\views.py", line 20, in get_queryset
    room_name = self.kwargs['room_name']
                ~~~~~~~~~~~^^^^^^^^^^^^^
KeyError: 'room_name'
ERROR 2025-08-24 10:34:21,385 log Internal Server Error: /chat/chat/room_list/
Traceback (most recent call last):
  File "C:\Users\Administrator\dl\.venv\Lib\site-packages\asgiref\sync.py", line 489, in thread_handler
    raise exc_info[1]
  File "C:\Users\Administrator\dl\.venv\Lib\site-packages\django\core\handlers\exception.py", line 42, in inner
    response = await get_response(request)
               ^^^^^^^^^^^^^^^^^^^^^^^^^^^
  File "C:\Users\Administrator\dl\.venv\Lib\site-packages\asgiref\sync.py", line 489, in thread_handler
    raise exc_info[1]
  File "C:\Users\Administrator\dl\.venv\Lib\site-packages\django\core\handlers\base.py", line 253, in _get_response_async
    response = await wrapped_callback(
               ^^^^^^^^^^^^^^^^^^^^^^^
        request, *callback_args, **callback_kwargs
        ^^^^^^^^^^^^^^^^^^^^^^^^^^^^^^^^^^^^^^^^^^
    )
    ^
  File "C:\Users\Administrator\dl\.venv\Lib\site-packages\asgiref\sync.py", line 439, in __call__
    ret = await asyncio.shield(exec_coro)
          ^^^^^^^^^^^^^^^^^^^^^^^^^^^^^^^
  File "C:\python\Lib\concurrent\futures\thread.py", line 59, in run
    result = self.fn(*self.args, **self.kwargs)
  File "C:\Users\Administrator\dl\.venv\Lib\site-packages\asgiref\sync.py", line 493, in thread_handler
    return func(*args, **kwargs)
  File "C:\Users\Administrator\dl\.venv\Lib\site-packages\django\views\generic\base.py", line 105, in view
    return self.dispatch(request, *args, **kwargs)
           ~~~~~~~~~~~~~^^^^^^^^^^^^^^^^^^^^^^^^^^
  File "C:\Users\Administrator\dl\.venv\Lib\site-packages\django\views\generic\base.py", line 144, in dispatch
    return handler(request, *args, **kwargs)
  File "C:\Users\Administrator\dl\.venv\Lib\site-packages\django\views\generic\list.py", line 158, in get
    self.object_list = self.get_queryset()
                       ~~~~~~~~~~~~~~~~~^^
  File "C:\Users\Administrator\dl\gerenzhuye\chat\views.py", line 20, in get_queryset
    room_name = self.kwargs['room_name']
                ~~~~~~~~~~~^^^^^^^^^^^^^
KeyError: 'room_name'
ERROR 2025-08-24 10:38:07,297 log Internal Server Error: /chat/chat/room_list/
Traceback (most recent call last):
  File "C:\Users\Administrator\dl\.venv\Lib\site-packages\django\db\backends\utils.py", line 105, in _execute
    return self.cursor.execute(sql, params)
           ~~~~~~~~~~~~~~~~~~~^^^^^^^^^^^^^
  File "C:\Users\Administrator\dl\.venv\Lib\site-packages\django\db\backends\sqlite3\base.py", line 360, in execute
    return super().execute(query, params)
           ~~~~~~~~~~~~~~~^^^^^^^^^^^^^^^
sqlite3.OperationalError: no such table: chat_room

The above exception was the direct cause of the following exception:

Traceback (most recent call last):
  File "C:\Users\Administrator\dl\.venv\Lib\site-packages\asgiref\sync.py", line 489, in thread_handler
    raise exc_info[1]
  File "C:\Users\Administrator\dl\.venv\Lib\site-packages\django\core\handlers\exception.py", line 42, in inner
    response = await get_response(request)
               ^^^^^^^^^^^^^^^^^^^^^^^^^^^
  File "C:\Users\Administrator\dl\.venv\Lib\site-packages\asgiref\sync.py", line 489, in thread_handler
    raise exc_info[1]
  File "C:\Users\Administrator\dl\.venv\Lib\site-packages\django\core\handlers\base.py", line 253, in _get_response_async
    response = await wrapped_callback(
               ^^^^^^^^^^^^^^^^^^^^^^^
        request, *callback_args, **callback_kwargs
        ^^^^^^^^^^^^^^^^^^^^^^^^^^^^^^^^^^^^^^^^^^
    )
    ^
  File "C:\Users\Administrator\dl\.venv\Lib\site-packages\asgiref\sync.py", line 439, in __call__
    ret = await asyncio.shield(exec_coro)
          ^^^^^^^^^^^^^^^^^^^^^^^^^^^^^^^
  File "C:\python\Lib\concurrent\futures\thread.py", line 59, in run
    result = self.fn(*self.args, **self.kwargs)
  File "C:\Users\Administrator\dl\.venv\Lib\site-packages\asgiref\sync.py", line 493, in thread_handler
    return func(*args, **kwargs)
  File "C:\Users\Administrator\dl\.venv\Lib\site-packages\django\views\generic\base.py", line 105, in view
    return self.dispatch(request, *args, **kwargs)
           ~~~~~~~~~~~~~^^^^^^^^^^^^^^^^^^^^^^^^^^
  File "C:\Users\Administrator\dl\.venv\Lib\site-packages\django\views\generic\base.py", line 144, in dispatch
    return handler(request, *args, **kwargs)
  File "C:\Users\Administrator\dl\.venv\Lib\site-packages\django\views\generic\list.py", line 178, in get
    context = self.get_context_data()
  File "C:\Users\Administrator\dl\.venv\Lib\site-packages\django\views\generic\list.py", line 128, in get_context_data
    paginator, page, queryset, is_paginated = self.paginate_queryset(
                                              ~~~~~~~~~~~~~~~~~~~~~~^
        queryset, page_size
        ^^^^^^^^^^^^^^^^^^^
    )
    ^
  File "C:\Users\Administrator\dl\.venv\Lib\site-packages\django\views\generic\list.py", line 73, in paginate_queryset
    page = paginator.page(page_number)
  File "C:\Users\Administrator\dl\.venv\Lib\site-packages\django\core\paginator.py", line 89, in page
    number = self.validate_number(number)
  File "C:\Users\Administrator\dl\.venv\Lib\site-packages\django\core\paginator.py", line 70, in validate_number
    if number > self.num_pages:
                ^^^^^^^^^^^^^^
  File "C:\Users\Administrator\dl\.venv\Lib\site-packages\django\utils\functional.py", line 47, in __get__
    res = instance.__dict__[self.name] = self.func(instance)
                                         ~~~~~~~~~^^^^^^^^^^
  File "C:\Users\Administrator\dl\.venv\Lib\site-packages\django\core\paginator.py", line 116, in num_pages
    if self.count == 0 and not self.allow_empty_first_page:
       ^^^^^^^^^^
  File "C:\Users\Administrator\dl\.venv\Lib\site-packages\django\utils\functional.py", line 47, in __get__
    res = instance.__dict__[self.name] = self.func(instance)
                                         ~~~~~~~~~^^^^^^^^^^
  File "C:\Users\Administrator\dl\.venv\Lib\site-packages\django\core\paginator.py", line 110, in count
    return c()
  File "C:\Users\Administrator\dl\.venv\Lib\site-packages\django\db\models\query.py", line 604, in count
    return self.query.get_count(using=self.db)
           ~~~~~~~~~~~~~~~~~~~~^^^^^^^^^^^^^^^
  File "C:\Users\Administrator\dl\.venv\Lib\site-packages\django\db\models\sql\query.py", line 644, in get_count
    return obj.get_aggregation(using, {"__count": Count("*")})["__count"]
           ~~~~~~~~~~~~~~~~~~~^^^^^^^^^^^^^^^^^^^^^^^^^^^^^^^^
  File "C:\Users\Administrator\dl\.venv\Lib\site-packages\django\db\models\sql\query.py", line 626, in get_aggregation
    result = compiler.execute_sql(SINGLE)
  File "C:\Users\Administrator\dl\.venv\Lib\site-packages\django\db\models\sql\compiler.py", line 1623, in execute_sql
    cursor.execute(sql, params)
    ~~~~~~~~~~~~~~^^^^^^^^^^^^^
  File "C:\Users\Administrator\dl\.venv\Lib\site-packages\django\db\backends\utils.py", line 122, in execute
    return super().execute(sql, params)
           ~~~~~~~~~~~~~~~^^^^^^^^^^^^^
  File "C:\Users\Administrator\dl\.venv\Lib\site-packages\django\db\backends\utils.py", line 79, in execute
    return self._execute_with_wrappers(
           ~~~~~~~~~~~~~~~~~~~~~~~~~~~^
        sql, params, many=False, executor=self._execute
        ^^^^^^^^^^^^^^^^^^^^^^^^^^^^^^^^^^^^^^^^^^^^^^^
    )
    ^
  File "C:\Users\Administrator\dl\.venv\Lib\site-packages\django\db\backends\utils.py", line 92, in _execute_with_wrappers
    return executor(sql, params, many, context)
  File "C:\Users\Administrator\dl\.venv\Lib\site-packages\django\db\backends\utils.py", line 100, in _execute
    with self.db.wrap_database_errors:
         ^^^^^^^^^^^^^^^^^^^^^^^^^^^^
  File "C:\Users\Administrator\dl\.venv\Lib\site-packages\django\db\utils.py", line 91, in __exit__
    raise dj_exc_value.with_traceback(traceback) from exc_value
  File "C:\Users\Administrator\dl\.venv\Lib\site-packages\django\db\backends\utils.py", line 105, in _execute
    return self.cursor.execute(sql, params)
           ~~~~~~~~~~~~~~~~~~~^^^^^^^^^^^^^
  File "C:\Users\Administrator\dl\.venv\Lib\site-packages\django\db\backends\sqlite3\base.py", line 360, in execute
    return super().execute(query, params)
           ~~~~~~~~~~~~~~~^^^^^^^^^^^^^^^
django.db.utils.OperationalError: no such table: chat_room
ERROR 2025-08-24 10:38:10,573 log Internal Server Error: /chat/chat/room_list/
Traceback (most recent call last):
  File "C:\Users\Administrator\dl\.venv\Lib\site-packages\django\db\backends\utils.py", line 105, in _execute
    return self.cursor.execute(sql, params)
           ~~~~~~~~~~~~~~~~~~~^^^^^^^^^^^^^
  File "C:\Users\Administrator\dl\.venv\Lib\site-packages\django\db\backends\sqlite3\base.py", line 360, in execute
    return super().execute(query, params)
           ~~~~~~~~~~~~~~~^^^^^^^^^^^^^^^
sqlite3.OperationalError: no such table: chat_room

The above exception was the direct cause of the following exception:

Traceback (most recent call last):
  File "C:\Users\Administrator\dl\.venv\Lib\site-packages\asgiref\sync.py", line 489, in thread_handler
    raise exc_info[1]
  File "C:\Users\Administrator\dl\.venv\Lib\site-packages\django\core\handlers\exception.py", line 42, in inner
    response = await get_response(request)
               ^^^^^^^^^^^^^^^^^^^^^^^^^^^
  File "C:\Users\Administrator\dl\.venv\Lib\site-packages\asgiref\sync.py", line 489, in thread_handler
    raise exc_info[1]
  File "C:\Users\Administrator\dl\.venv\Lib\site-packages\django\core\handlers\base.py", line 253, in _get_response_async
    response = await wrapped_callback(
               ^^^^^^^^^^^^^^^^^^^^^^^
        request, *callback_args, **callback_kwargs
        ^^^^^^^^^^^^^^^^^^^^^^^^^^^^^^^^^^^^^^^^^^
    )
    ^
  File "C:\Users\Administrator\dl\.venv\Lib\site-packages\asgiref\sync.py", line 439, in __call__
    ret = await asyncio.shield(exec_coro)
          ^^^^^^^^^^^^^^^^^^^^^^^^^^^^^^^
  File "C:\python\Lib\concurrent\futures\thread.py", line 59, in run
    result = self.fn(*self.args, **self.kwargs)
  File "C:\Users\Administrator\dl\.venv\Lib\site-packages\asgiref\sync.py", line 493, in thread_handler
    return func(*args, **kwargs)
  File "C:\Users\Administrator\dl\.venv\Lib\site-packages\django\views\generic\base.py", line 105, in view
    return self.dispatch(request, *args, **kwargs)
           ~~~~~~~~~~~~~^^^^^^^^^^^^^^^^^^^^^^^^^^
  File "C:\Users\Administrator\dl\.venv\Lib\site-packages\django\views\generic\base.py", line 144, in dispatch
    return handler(request, *args, **kwargs)
  File "C:\Users\Administrator\dl\.venv\Lib\site-packages\django\views\generic\list.py", line 178, in get
    context = self.get_context_data()
  File "C:\Users\Administrator\dl\.venv\Lib\site-packages\django\views\generic\list.py", line 128, in get_context_data
    paginator, page, queryset, is_paginated = self.paginate_queryset(
                                              ~~~~~~~~~~~~~~~~~~~~~~^
        queryset, page_size
        ^^^^^^^^^^^^^^^^^^^
    )
    ^
  File "C:\Users\Administrator\dl\.venv\Lib\site-packages\django\views\generic\list.py", line 73, in paginate_queryset
    page = paginator.page(page_number)
  File "C:\Users\Administrator\dl\.venv\Lib\site-packages\django\core\paginator.py", line 89, in page
    number = self.validate_number(number)
  File "C:\Users\Administrator\dl\.venv\Lib\site-packages\django\core\paginator.py", line 70, in validate_number
    if number > self.num_pages:
                ^^^^^^^^^^^^^^
  File "C:\Users\Administrator\dl\.venv\Lib\site-packages\django\utils\functional.py", line 47, in __get__
    res = instance.__dict__[self.name] = self.func(instance)
                                         ~~~~~~~~~^^^^^^^^^^
  File "C:\Users\Administrator\dl\.venv\Lib\site-packages\django\core\paginator.py", line 116, in num_pages
    if self.count == 0 and not self.allow_empty_first_page:
       ^^^^^^^^^^
  File "C:\Users\Administrator\dl\.venv\Lib\site-packages\django\utils\functional.py", line 47, in __get__
    res = instance.__dict__[self.name] = self.func(instance)
                                         ~~~~~~~~~^^^^^^^^^^
  File "C:\Users\Administrator\dl\.venv\Lib\site-packages\django\core\paginator.py", line 110, in count
    return c()
  File "C:\Users\Administrator\dl\.venv\Lib\site-packages\django\db\models\query.py", line 604, in count
    return self.query.get_count(using=self.db)
           ~~~~~~~~~~~~~~~~~~~~^^^^^^^^^^^^^^^
  File "C:\Users\Administrator\dl\.venv\Lib\site-packages\django\db\models\sql\query.py", line 644, in get_count
    return obj.get_aggregation(using, {"__count": Count("*")})["__count"]
           ~~~~~~~~~~~~~~~~~~~^^^^^^^^^^^^^^^^^^^^^^^^^^^^^^^^
  File "C:\Users\Administrator\dl\.venv\Lib\site-packages\django\db\models\sql\query.py", line 626, in get_aggregation
    result = compiler.execute_sql(SINGLE)
  File "C:\Users\Administrator\dl\.venv\Lib\site-packages\django\db\models\sql\compiler.py", line 1623, in execute_sql
    cursor.execute(sql, params)
    ~~~~~~~~~~~~~~^^^^^^^^^^^^^
  File "C:\Users\Administrator\dl\.venv\Lib\site-packages\django\db\backends\utils.py", line 122, in execute
    return super().execute(sql, params)
           ~~~~~~~~~~~~~~~^^^^^^^^^^^^^
  File "C:\Users\Administrator\dl\.venv\Lib\site-packages\django\db\backends\utils.py", line 79, in execute
    return self._execute_with_wrappers(
           ~~~~~~~~~~~~~~~~~~~~~~~~~~~^
        sql, params, many=False, executor=self._execute
        ^^^^^^^^^^^^^^^^^^^^^^^^^^^^^^^^^^^^^^^^^^^^^^^
    )
    ^
  File "C:\Users\Administrator\dl\.venv\Lib\site-packages\django\db\backends\utils.py", line 92, in _execute_with_wrappers
    return executor(sql, params, many, context)
  File "C:\Users\Administrator\dl\.venv\Lib\site-packages\django\db\backends\utils.py", line 100, in _execute
    with self.db.wrap_database_errors:
         ^^^^^^^^^^^^^^^^^^^^^^^^^^^^
  File "C:\Users\Administrator\dl\.venv\Lib\site-packages\django\db\utils.py", line 91, in __exit__
    raise dj_exc_value.with_traceback(traceback) from exc_value
  File "C:\Users\Administrator\dl\.venv\Lib\site-packages\django\db\backends\utils.py", line 105, in _execute
    return self.cursor.execute(sql, params)
           ~~~~~~~~~~~~~~~~~~~^^^^^^^^^^^^^
  File "C:\Users\Administrator\dl\.venv\Lib\site-packages\django\db\backends\sqlite3\base.py", line 360, in execute
    return super().execute(query, params)
           ~~~~~~~~~~~~~~~^^^^^^^^^^^^^^^
django.db.utils.OperationalError: no such table: chat_room
WARNING 2025-08-24 11:16:44,421 log Not Found: /favicon.ico
WARNING 2025-08-24 11:17:20,644 log Not Found: /favicon.ico
WARNING 2025-08-24 11:17:57,184 log Not Found: /favicon.ico
WARNING 2025-08-24 11:34:21,100 log Not Found: /favicon.ico
WARNING 2025-08-24 11:34:24,376 log Not Found: /favicon.ico
ERROR 2025-08-24 13:56:39,185 log Internal Server Error: /chat/chat/room_list/
Traceback (most recent call last):
  File "C:\Users\Administrator\dl\.venv\Lib\site-packages\django\db\backends\utils.py", line 105, in _execute
    return self.cursor.execute(sql, params)
           ~~~~~~~~~~~~~~~~~~~^^^^^^^^^^^^^
  File "C:\Users\Administrator\dl\.venv\Lib\site-packages\django\db\backends\sqlite3\base.py", line 360, in execute
    return super().execute(query, params)
           ~~~~~~~~~~~~~~~^^^^^^^^^^^^^^^
sqlite3.OperationalError: no such column: chat_room.member_count

The above exception was the direct cause of the following exception:

Traceback (most recent call last):
  File "C:\Users\Administrator\dl\.venv\Lib\site-packages\asgiref\sync.py", line 489, in thread_handler
    raise exc_info[1]
  File "C:\Users\Administrator\dl\.venv\Lib\site-packages\django\core\handlers\exception.py", line 42, in inner
    response = await get_response(request)
               ^^^^^^^^^^^^^^^^^^^^^^^^^^^
  File "C:\Users\Administrator\dl\.venv\Lib\site-packages\asgiref\sync.py", line 489, in thread_handler
    raise exc_info[1]
  File "C:\Users\Administrator\dl\.venv\Lib\site-packages\django\core\handlers\base.py", line 284, in _get_response_async
    response = await sync_to_async(
               ^^^^^^^^^^^^^^^^^^^^
        response.render, thread_sensitive=True
        ^^^^^^^^^^^^^^^^^^^^^^^^^^^^^^^^^^^^^^
    )()
    ^^^
  File "C:\Users\Administrator\dl\.venv\Lib\site-packages\asgiref\sync.py", line 439, in __call__
    ret = await asyncio.shield(exec_coro)
          ^^^^^^^^^^^^^^^^^^^^^^^^^^^^^^^
  File "C:\python\Lib\concurrent\futures\thread.py", line 59, in run
    result = self.fn(*self.args, **self.kwargs)
  File "C:\Users\Administrator\dl\.venv\Lib\site-packages\asgiref\sync.py", line 493, in thread_handler
    return func(*args, **kwargs)
  File "C:\Users\Administrator\dl\.venv\Lib\site-packages\django\template\response.py", line 114, in render
    self.content = self.rendered_content
                   ^^^^^^^^^^^^^^^^^^^^^
  File "C:\Users\Administrator\dl\.venv\Lib\site-packages\django\template\response.py", line 92, in rendered_content
    return template.render(context, self._request)
           ~~~~~~~~~~~~~~~^^^^^^^^^^^^^^^^^^^^^^^^
  File "C:\Users\Administrator\dl\.venv\Lib\site-packages\django\template\backends\django.py", line 107, in render
    return self.template.render(context)
           ~~~~~~~~~~~~~~~~~~~~^^^^^^^^^
  File "C:\Users\Administrator\dl\.venv\Lib\site-packages\django\template\base.py", line 171, in render
    return self._render(context)
           ~~~~~~~~~~~~^^^^^^^^^
  File "C:\Users\Administrator\dl\.venv\Lib\site-packages\django\template\base.py", line 163, in _render
    return self.nodelist.render(context)
           ~~~~~~~~~~~~~~~~~~~~^^^^^^^^^
  File "C:\Users\Administrator\dl\.venv\Lib\site-packages\django\template\base.py", line 1016, in render
    return SafeString("".join([node.render_annotated(context) for node in self]))
                               ~~~~~~~~~~~~~~~~~~~~~^^^^^^^^^
  File "C:\Users\Administrator\dl\.venv\Lib\site-packages\django\template\base.py", line 977, in render_annotated
    return self.render(context)
           ~~~~~~~~~~~^^^^^^^^^
  File "C:\Users\Administrator\dl\.venv\Lib\site-packages\django\template\loader_tags.py", line 159, in render
    return compiled_parent._render(context)
           ~~~~~~~~~~~~~~~~~~~~~~~^^^^^^^^^
  File "C:\Users\Administrator\dl\.venv\Lib\site-packages\django\template\base.py", line 163, in _render
    return self.nodelist.render(context)
           ~~~~~~~~~~~~~~~~~~~~^^^^^^^^^
  File "C:\Users\Administrator\dl\.venv\Lib\site-packages\django\template\base.py", line 1016, in render
    return SafeString("".join([node.render_annotated(context) for node in self]))
                               ~~~~~~~~~~~~~~~~~~~~~^^^^^^^^^
  File "C:\Users\Administrator\dl\.venv\Lib\site-packages\django\template\base.py", line 977, in render_annotated
    return self.render(context)
           ~~~~~~~~~~~^^^^^^^^^
  File "C:\Users\Administrator\dl\.venv\Lib\site-packages\django\template\loader_tags.py", line 65, in render
    result = block.nodelist.render(context)
  File "C:\Users\Administrator\dl\.venv\Lib\site-packages\django\template\base.py", line 1016, in render
    return SafeString("".join([node.render_annotated(context) for node in self]))
                               ~~~~~~~~~~~~~~~~~~~~~^^^^^^^^^
  File "C:\Users\Administrator\dl\.venv\Lib\site-packages\django\template\base.py", line 977, in render_annotated
    return self.render(context)
           ~~~~~~~~~~~^^^^^^^^^
  File "C:\Users\Administrator\dl\.venv\Lib\site-packages\django\template\defaulttags.py", line 199, in render
    len_values = len(values)
  File "C:\Users\Administrator\dl\.venv\Lib\site-packages\django\db\models\query.py", line 366, in __len__
    self._fetch_all()
    ~~~~~~~~~~~~~~~^^
  File "C:\Users\Administrator\dl\.venv\Lib\site-packages\django\db\models\query.py", line 1949, in _fetch_all
    self._result_cache = list(self._iterable_class(self))
                         ~~~~^^^^^^^^^^^^^^^^^^^^^^^^^^^^
  File "C:\Users\Administrator\dl\.venv\Lib\site-packages\django\db\models\query.py", line 91, in __iter__
    results = compiler.execute_sql(
        chunked_fetch=self.chunked_fetch, chunk_size=self.chunk_size
    )
  File "C:\Users\Administrator\dl\.venv\Lib\site-packages\django\db\models\sql\compiler.py", line 1623, in execute_sql
    cursor.execute(sql, params)
    ~~~~~~~~~~~~~~^^^^^^^^^^^^^
  File "C:\Users\Administrator\dl\.venv\Lib\site-packages\django\db\backends\utils.py", line 122, in execute
    return super().execute(sql, params)
           ~~~~~~~~~~~~~~~^^^^^^^^^^^^^
  File "C:\Users\Administrator\dl\.venv\Lib\site-packages\django\db\backends\utils.py", line 79, in execute
    return self._execute_with_wrappers(
           ~~~~~~~~~~~~~~~~~~~~~~~~~~~^
        sql, params, many=False, executor=self._execute
        ^^^^^^^^^^^^^^^^^^^^^^^^^^^^^^^^^^^^^^^^^^^^^^^
    )
    ^
  File "C:\Users\Administrator\dl\.venv\Lib\site-packages\django\db\backends\utils.py", line 92, in _execute_with_wrappers
    return executor(sql, params, many, context)
  File "C:\Users\Administrator\dl\.venv\Lib\site-packages\django\db\backends\utils.py", line 100, in _execute
    with self.db.wrap_database_errors:
         ^^^^^^^^^^^^^^^^^^^^^^^^^^^^
  File "C:\Users\Administrator\dl\.venv\Lib\site-packages\django\db\utils.py", line 91, in __exit__
    raise dj_exc_value.with_traceback(traceback) from exc_value
  File "C:\Users\Administrator\dl\.venv\Lib\site-packages\django\db\backends\utils.py", line 105, in _execute
    return self.cursor.execute(sql, params)
           ~~~~~~~~~~~~~~~~~~~^^^^^^^^^^^^^
  File "C:\Users\Administrator\dl\.venv\Lib\site-packages\django\db\backends\sqlite3\base.py", line 360, in execute
    return super().execute(query, params)
           ~~~~~~~~~~~~~~~^^^^^^^^^^^^^^^
django.db.utils.OperationalError: no such column: chat_room.member_count
ERROR 2025-08-24 14:15:51,368 log Internal Server Error: /chat/room/default/
Traceback (most recent call last):
  File "C:\Users\Administrator\dl\.venv\Lib\site-packages\asgiref\sync.py", line 489, in thread_handler
    raise exc_info[1]
  File "C:\Users\Administrator\dl\.venv\Lib\site-packages\django\core\handlers\exception.py", line 42, in inner
    response = await get_response(request)
               ^^^^^^^^^^^^^^^^^^^^^^^^^^^
  File "C:\Users\Administrator\dl\.venv\Lib\site-packages\asgiref\sync.py", line 489, in thread_handler
    raise exc_info[1]
  File "C:\Users\Administrator\dl\.venv\Lib\site-packages\django\core\handlers\base.py", line 253, in _get_response_async
    response = await wrapped_callback(
               ^^^^^^^^^^^^^^^^^^^^^^^
        request, *callback_args, **callback_kwargs
        ^^^^^^^^^^^^^^^^^^^^^^^^^^^^^^^^^^^^^^^^^^
    )
    ^
  File "C:\Users\Administrator\dl\.venv\Lib\site-packages\asgiref\sync.py", line 439, in __call__
    ret = await asyncio.shield(exec_coro)
          ^^^^^^^^^^^^^^^^^^^^^^^^^^^^^^^
  File "C:\python\Lib\concurrent\futures\thread.py", line 59, in run
    result = self.fn(*self.args, **self.kwargs)
  File "C:\Users\Administrator\dl\.venv\Lib\site-packages\asgiref\sync.py", line 493, in thread_handler
    return func(*args, **kwargs)
  File "C:\Users\Administrator\dl\gerenzhuye\chat\views.py", line 10, in chat_room
    chatroom = Room.objects.get(name=room_name)
  File "C:\Users\Administrator\dl\.venv\Lib\site-packages\django\db\models\manager.py", line 87, in manager_method
    return getattr(self.get_queryset(), name)(*args, **kwargs)
           ~~~~~~~~~~~~~~~~~~~~~~~~~~~~~~~~~~^^^^^^^^^^^^^^^^^
  File "C:\Users\Administrator\dl\.venv\Lib\site-packages\django\db\models\query.py", line 619, in get
    clone = self._chain() if self.query.combinator else self.filter(*args, **kwargs)
                                                        ~~~~~~~~~~~^^^^^^^^^^^^^^^^^
  File "C:\Users\Administrator\dl\.venv\Lib\site-packages\django\db\models\query.py", line 1493, in filter
    return self._filter_or_exclude(False, args, kwargs)
           ~~~~~~~~~~~~~~~~~~~~~~~^^^^^^^^^^^^^^^^^^^^^
  File "C:\Users\Administrator\dl\.venv\Lib\site-packages\django\db\models\query.py", line 1511, in _filter_or_exclude
    clone._filter_or_exclude_inplace(negate, args, kwargs)
    ~~~~~~~~~~~~~~~~~~~~~~~~~~~~~~~~^^^^^^^^^^^^^^^^^^^^^^
  File "C:\Users\Administrator\dl\.venv\Lib\site-packages\django\db\models\query.py", line 1518, in _filter_or_exclude_inplace
    self._query.add_q(Q(*args, **kwargs))
    ~~~~~~~~~~~~~~~~~^^^^^^^^^^^^^^^^^^^^
  File "C:\Users\Administrator\dl\.venv\Lib\site-packages\django\db\models\sql\query.py", line 1646, in add_q
    clause, _ = self._add_q(q_object, can_reuse)
                ~~~~~~~~~~~^^^^^^^^^^^^^^^^^^^^^
  File "C:\Users\Administrator\dl\.venv\Lib\site-packages\django\db\models\sql\query.py", line 1678, in _add_q
    child_clause, needed_inner = self.build_filter(
                                 ~~~~~~~~~~~~~~~~~^
        child,
        ^^^^^^
    ...<7 lines>...
        update_join_types=update_join_types,
        ^^^^^^^^^^^^^^^^^^^^^^^^^^^^^^^^^^^^
    )
    ^
  File "C:\Users\Administrator\dl\.venv\Lib\site-packages\django\db\models\sql\query.py", line 1526, in build_filter
    lookups, parts, reffed_expression = self.solve_lookup_type(arg, summarize)
                                        ~~~~~~~~~~~~~~~~~~~~~~^^^^^^^^^^^^^^^^
  File "C:\Users\Administrator\dl\.venv\Lib\site-packages\django\db\models\sql\query.py", line 1333, in solve_lookup_type
    _, field, _, lookup_parts = self.names_to_path(lookup_splitted, self.get_meta())
                                ~~~~~~~~~~~~~~~~~~^^^^^^^^^^^^^^^^^^^^^^^^^^^^^^^^^^
  File "C:\Users\Administrator\dl\.venv\Lib\site-packages\django\db\models\sql\query.py", line 1805, in names_to_path
    raise FieldError(
    ...<2 lines>...
    )
django.core.exceptions.FieldError: Cannot resolve keyword 'name' into field. Choices are: create_time, member_count, room2chat, room_id, room_name, room_type
ERROR 2025-08-24 14:16:54,122 log Internal Server Error: /chat/room/default/
Traceback (most recent call last):
  File "C:\Users\Administrator\dl\.venv\Lib\site-packages\django\db\backends\utils.py", line 105, in _execute
    return self.cursor.execute(sql, params)
           ~~~~~~~~~~~~~~~~~~~^^^^^^^^^^^^^
  File "C:\Users\Administrator\dl\.venv\Lib\site-packages\django\db\backends\sqlite3\base.py", line 360, in execute
    return super().execute(query, params)
           ~~~~~~~~~~~~~~~^^^^^^^^^^^^^^^
sqlite3.OperationalError: no such column: chat_room.member_count

The above exception was the direct cause of the following exception:

Traceback (most recent call last):
  File "C:\Users\Administrator\dl\.venv\Lib\site-packages\asgiref\sync.py", line 489, in thread_handler
    raise exc_info[1]
  File "C:\Users\Administrator\dl\.venv\Lib\site-packages\django\core\handlers\exception.py", line 42, in inner
    response = await get_response(request)
               ^^^^^^^^^^^^^^^^^^^^^^^^^^^
  File "C:\Users\Administrator\dl\.venv\Lib\site-packages\asgiref\sync.py", line 489, in thread_handler
    raise exc_info[1]
  File "C:\Users\Administrator\dl\.venv\Lib\site-packages\django\core\handlers\base.py", line 253, in _get_response_async
    response = await wrapped_callback(
               ^^^^^^^^^^^^^^^^^^^^^^^
        request, *callback_args, **callback_kwargs
        ^^^^^^^^^^^^^^^^^^^^^^^^^^^^^^^^^^^^^^^^^^
    )
    ^
  File "C:\Users\Administrator\dl\.venv\Lib\site-packages\asgiref\sync.py", line 439, in __call__
    ret = await asyncio.shield(exec_coro)
          ^^^^^^^^^^^^^^^^^^^^^^^^^^^^^^^
  File "C:\python\Lib\concurrent\futures\thread.py", line 59, in run
    result = self.fn(*self.args, **self.kwargs)
  File "C:\Users\Administrator\dl\.venv\Lib\site-packages\asgiref\sync.py", line 493, in thread_handler
    return func(*args, **kwargs)
  File "C:\Users\Administrator\dl\gerenzhuye\chat\views.py", line 10, in chat_room
    chatroom = Room.objects.get(room_name=room_name)
  File "C:\Users\Administrator\dl\.venv\Lib\site-packages\django\db\models\manager.py", line 87, in manager_method
    return getattr(self.get_queryset(), name)(*args, **kwargs)
           ~~~~~~~~~~~~~~~~~~~~~~~~~~~~~~~~~~^^^^^^^^^^^^^^^^^
  File "C:\Users\Administrator\dl\.venv\Lib\site-packages\django\db\models\query.py", line 629, in get
    num = len(clone)
  File "C:\Users\Administrator\dl\.venv\Lib\site-packages\django\db\models\query.py", line 366, in __len__
    self._fetch_all()
    ~~~~~~~~~~~~~~~^^
  File "C:\Users\Administrator\dl\.venv\Lib\site-packages\django\db\models\query.py", line 1949, in _fetch_all
    self._result_cache = list(self._iterable_class(self))
                         ~~~~^^^^^^^^^^^^^^^^^^^^^^^^^^^^
  File "C:\Users\Administrator\dl\.venv\Lib\site-packages\django\db\models\query.py", line 91, in __iter__
    results = compiler.execute_sql(
        chunked_fetch=self.chunked_fetch, chunk_size=self.chunk_size
    )
  File "C:\Users\Administrator\dl\.venv\Lib\site-packages\django\db\models\sql\compiler.py", line 1623, in execute_sql
    cursor.execute(sql, params)
    ~~~~~~~~~~~~~~^^^^^^^^^^^^^
  File "C:\Users\Administrator\dl\.venv\Lib\site-packages\django\db\backends\utils.py", line 122, in execute
    return super().execute(sql, params)
           ~~~~~~~~~~~~~~~^^^^^^^^^^^^^
  File "C:\Users\Administrator\dl\.venv\Lib\site-packages\django\db\backends\utils.py", line 79, in execute
    return self._execute_with_wrappers(
           ~~~~~~~~~~~~~~~~~~~~~~~~~~~^
        sql, params, many=False, executor=self._execute
        ^^^^^^^^^^^^^^^^^^^^^^^^^^^^^^^^^^^^^^^^^^^^^^^
    )
    ^
  File "C:\Users\Administrator\dl\.venv\Lib\site-packages\django\db\backends\utils.py", line 92, in _execute_with_wrappers
    return executor(sql, params, many, context)
  File "C:\Users\Administrator\dl\.venv\Lib\site-packages\django\db\backends\utils.py", line 100, in _execute
    with self.db.wrap_database_errors:
         ^^^^^^^^^^^^^^^^^^^^^^^^^^^^
  File "C:\Users\Administrator\dl\.venv\Lib\site-packages\django\db\utils.py", line 91, in __exit__
    raise dj_exc_value.with_traceback(traceback) from exc_value
  File "C:\Users\Administrator\dl\.venv\Lib\site-packages\django\db\backends\utils.py", line 105, in _execute
    return self.cursor.execute(sql, params)
           ~~~~~~~~~~~~~~~~~~~^^^^^^^^^^^^^
  File "C:\Users\Administrator\dl\.venv\Lib\site-packages\django\db\backends\sqlite3\base.py", line 360, in execute
    return super().execute(query, params)
           ~~~~~~~~~~~~~~~^^^^^^^^^^^^^^^
django.db.utils.OperationalError: no such column: chat_room.member_count
ERROR 2025-08-24 14:16:56,484 log Internal Server Error: /chat/room/default/
Traceback (most recent call last):
  File "C:\Users\Administrator\dl\.venv\Lib\site-packages\django\db\backends\utils.py", line 105, in _execute
    return self.cursor.execute(sql, params)
           ~~~~~~~~~~~~~~~~~~~^^^^^^^^^^^^^
  File "C:\Users\Administrator\dl\.venv\Lib\site-packages\django\db\backends\sqlite3\base.py", line 360, in execute
    return super().execute(query, params)
           ~~~~~~~~~~~~~~~^^^^^^^^^^^^^^^
sqlite3.OperationalError: no such column: chat_room.member_count

The above exception was the direct cause of the following exception:

Traceback (most recent call last):
  File "C:\Users\Administrator\dl\.venv\Lib\site-packages\asgiref\sync.py", line 489, in thread_handler
    raise exc_info[1]
  File "C:\Users\Administrator\dl\.venv\Lib\site-packages\django\core\handlers\exception.py", line 42, in inner
    response = await get_response(request)
               ^^^^^^^^^^^^^^^^^^^^^^^^^^^
  File "C:\Users\Administrator\dl\.venv\Lib\site-packages\asgiref\sync.py", line 489, in thread_handler
    raise exc_info[1]
  File "C:\Users\Administrator\dl\.venv\Lib\site-packages\django\core\handlers\base.py", line 253, in _get_response_async
    response = await wrapped_callback(
               ^^^^^^^^^^^^^^^^^^^^^^^
        request, *callback_args, **callback_kwargs
        ^^^^^^^^^^^^^^^^^^^^^^^^^^^^^^^^^^^^^^^^^^
    )
    ^
  File "C:\Users\Administrator\dl\.venv\Lib\site-packages\asgiref\sync.py", line 439, in __call__
    ret = await asyncio.shield(exec_coro)
          ^^^^^^^^^^^^^^^^^^^^^^^^^^^^^^^
  File "C:\python\Lib\concurrent\futures\thread.py", line 59, in run
    result = self.fn(*self.args, **self.kwargs)
  File "C:\Users\Administrator\dl\.venv\Lib\site-packages\asgiref\sync.py", line 493, in thread_handler
    return func(*args, **kwargs)
  File "C:\Users\Administrator\dl\gerenzhuye\chat\views.py", line 10, in chat_room
    chatroom = Room.objects.get(room_name=room_name)
  File "C:\Users\Administrator\dl\.venv\Lib\site-packages\django\db\models\manager.py", line 87, in manager_method
    return getattr(self.get_queryset(), name)(*args, **kwargs)
           ~~~~~~~~~~~~~~~~~~~~~~~~~~~~~~~~~~^^^^^^^^^^^^^^^^^
  File "C:\Users\Administrator\dl\.venv\Lib\site-packages\django\db\models\query.py", line 629, in get
    num = len(clone)
  File "C:\Users\Administrator\dl\.venv\Lib\site-packages\django\db\models\query.py", line 366, in __len__
    self._fetch_all()
    ~~~~~~~~~~~~~~~^^
  File "C:\Users\Administrator\dl\.venv\Lib\site-packages\django\db\models\query.py", line 1949, in _fetch_all
    self._result_cache = list(self._iterable_class(self))
                         ~~~~^^^^^^^^^^^^^^^^^^^^^^^^^^^^
  File "C:\Users\Administrator\dl\.venv\Lib\site-packages\django\db\models\query.py", line 91, in __iter__
    results = compiler.execute_sql(
        chunked_fetch=self.chunked_fetch, chunk_size=self.chunk_size
    )
  File "C:\Users\Administrator\dl\.venv\Lib\site-packages\django\db\models\sql\compiler.py", line 1623, in execute_sql
    cursor.execute(sql, params)
    ~~~~~~~~~~~~~~^^^^^^^^^^^^^
  File "C:\Users\Administrator\dl\.venv\Lib\site-packages\django\db\backends\utils.py", line 122, in execute
    return super().execute(sql, params)
           ~~~~~~~~~~~~~~~^^^^^^^^^^^^^
  File "C:\Users\Administrator\dl\.venv\Lib\site-packages\django\db\backends\utils.py", line 79, in execute
    return self._execute_with_wrappers(
           ~~~~~~~~~~~~~~~~~~~~~~~~~~~^
        sql, params, many=False, executor=self._execute
        ^^^^^^^^^^^^^^^^^^^^^^^^^^^^^^^^^^^^^^^^^^^^^^^
    )
    ^
  File "C:\Users\Administrator\dl\.venv\Lib\site-packages\django\db\backends\utils.py", line 92, in _execute_with_wrappers
    return executor(sql, params, many, context)
  File "C:\Users\Administrator\dl\.venv\Lib\site-packages\django\db\backends\utils.py", line 100, in _execute
    with self.db.wrap_database_errors:
         ^^^^^^^^^^^^^^^^^^^^^^^^^^^^
  File "C:\Users\Administrator\dl\.venv\Lib\site-packages\django\db\utils.py", line 91, in __exit__
    raise dj_exc_value.with_traceback(traceback) from exc_value
  File "C:\Users\Administrator\dl\.venv\Lib\site-packages\django\db\backends\utils.py", line 105, in _execute
    return self.cursor.execute(sql, params)
           ~~~~~~~~~~~~~~~~~~~^^^^^^^^^^^^^
  File "C:\Users\Administrator\dl\.venv\Lib\site-packages\django\db\backends\sqlite3\base.py", line 360, in execute
    return super().execute(query, params)
           ~~~~~~~~~~~~~~~^^^^^^^^^^^^^^^
django.db.utils.OperationalError: no such column: chat_room.member_count
ERROR 2025-08-24 14:25:09,102 log Internal Server Error: /chat/room/default/
Traceback (most recent call last):
  File "C:\Users\Administrator\dl\.venv\Lib\site-packages\asgiref\sync.py", line 489, in thread_handler
    raise exc_info[1]
  File "C:\Users\Administrator\dl\.venv\Lib\site-packages\django\core\handlers\exception.py", line 42, in inner
    response = await get_response(request)
               ^^^^^^^^^^^^^^^^^^^^^^^^^^^
  File "C:\Users\Administrator\dl\.venv\Lib\site-packages\asgiref\sync.py", line 489, in thread_handler
    raise exc_info[1]
  File "C:\Users\Administrator\dl\.venv\Lib\site-packages\django\core\handlers\base.py", line 253, in _get_response_async
    response = await wrapped_callback(
               ^^^^^^^^^^^^^^^^^^^^^^^
        request, *callback_args, **callback_kwargs
        ^^^^^^^^^^^^^^^^^^^^^^^^^^^^^^^^^^^^^^^^^^
    )
    ^
  File "C:\Users\Administrator\dl\.venv\Lib\site-packages\asgiref\sync.py", line 439, in __call__
    ret = await asyncio.shield(exec_coro)
          ^^^^^^^^^^^^^^^^^^^^^^^^^^^^^^^
  File "C:\python\Lib\concurrent\futures\thread.py", line 59, in run
    result = self.fn(*self.args, **self.kwargs)
  File "C:\Users\Administrator\dl\.venv\Lib\site-packages\asgiref\sync.py", line 493, in thread_handler
    return func(*args, **kwargs)
  File "C:\Users\Administrator\dl\gerenzhuye\chat\views.py", line 10, in chat_room
    chatroom = Room.objects.get(room_name=room_name)
  File "C:\Users\Administrator\dl\.venv\Lib\site-packages\django\db\models\manager.py", line 87, in manager_method
    return getattr(self.get_queryset(), name)(*args, **kwargs)
           ~~~~~~~~~~~~~~~~~~~~~~~~~~~~~~~~~~^^^^^^^^^^^^^^^^^
  File "C:\Users\Administrator\dl\.venv\Lib\site-packages\django\db\models\query.py", line 633, in get
    raise self.model.DoesNotExist(
        "%s matching query does not exist." % self.model._meta.object_name
    )
chat.models.Room.DoesNotExist: Room matching query does not exist.
ERROR 2025-08-24 14:28:41,754 log Internal Server Error: /chat/room/default/
Traceback (most recent call last):
  File "C:\Users\Administrator\dl\.venv\Lib\site-packages\asgiref\sync.py", line 489, in thread_handler
    raise exc_info[1]
  File "C:\Users\Administrator\dl\.venv\Lib\site-packages\django\core\handlers\exception.py", line 42, in inner
    response = await get_response(request)
               ^^^^^^^^^^^^^^^^^^^^^^^^^^^
  File "C:\Users\Administrator\dl\.venv\Lib\site-packages\asgiref\sync.py", line 489, in thread_handler
    raise exc_info[1]
  File "C:\Users\Administrator\dl\.venv\Lib\site-packages\django\core\handlers\base.py", line 253, in _get_response_async
    response = await wrapped_callback(
               ^^^^^^^^^^^^^^^^^^^^^^^
        request, *callback_args, **callback_kwargs
        ^^^^^^^^^^^^^^^^^^^^^^^^^^^^^^^^^^^^^^^^^^
    )
    ^
  File "C:\Users\Administrator\dl\.venv\Lib\site-packages\asgiref\sync.py", line 439, in __call__
    ret = await asyncio.shield(exec_coro)
          ^^^^^^^^^^^^^^^^^^^^^^^^^^^^^^^
  File "C:\python\Lib\concurrent\futures\thread.py", line 59, in run
    result = self.fn(*self.args, **self.kwargs)
  File "C:\Users\Administrator\dl\.venv\Lib\site-packages\asgiref\sync.py", line 493, in thread_handler
    return func(*args, **kwargs)
  File "C:\Users\Administrator\dl\gerenzhuye\chat\views.py", line 10, in chat_room
    chatroom = Room.objects.get(room_name=room_name)
  File "C:\Users\Administrator\dl\.venv\Lib\site-packages\django\db\models\manager.py", line 87, in manager_method
    return getattr(self.get_queryset(), name)(*args, **kwargs)
           ~~~~~~~~~~~~~~~~~~~~~~~~~~~~~~~~~~^^^^^^^^^^^^^^^^^
  File "C:\Users\Administrator\dl\.venv\Lib\site-packages\django\db\models\query.py", line 633, in get
    raise self.model.DoesNotExist(
        "%s matching query does not exist." % self.model._meta.object_name
    )
chat.models.Room.DoesNotExist: Room matching query does not exist.
ERROR 2025-08-24 14:32:04,801 log Internal Server Error: /chat/room/default/
Traceback (most recent call last):
  File "C:\Users\Administrator\dl\.venv\Lib\site-packages\asgiref\sync.py", line 489, in thread_handler
    raise exc_info[1]
  File "C:\Users\Administrator\dl\.venv\Lib\site-packages\django\core\handlers\exception.py", line 42, in inner
    response = await get_response(request)
               ^^^^^^^^^^^^^^^^^^^^^^^^^^^
  File "C:\Users\Administrator\dl\.venv\Lib\site-packages\asgiref\sync.py", line 489, in thread_handler
    raise exc_info[1]
  File "C:\Users\Administrator\dl\.venv\Lib\site-packages\django\core\handlers\base.py", line 253, in _get_response_async
    response = await wrapped_callback(
               ^^^^^^^^^^^^^^^^^^^^^^^
        request, *callback_args, **callback_kwargs
        ^^^^^^^^^^^^^^^^^^^^^^^^^^^^^^^^^^^^^^^^^^
    )
    ^
  File "C:\Users\Administrator\dl\.venv\Lib\site-packages\asgiref\sync.py", line 439, in __call__
    ret = await asyncio.shield(exec_coro)
          ^^^^^^^^^^^^^^^^^^^^^^^^^^^^^^^
  File "C:\python\Lib\concurrent\futures\thread.py", line 59, in run
    result = self.fn(*self.args, **self.kwargs)
  File "C:\Users\Administrator\dl\.venv\Lib\site-packages\asgiref\sync.py", line 493, in thread_handler
    return func(*args, **kwargs)
  File "C:\Users\Administrator\dl\gerenzhuye\chat\views.py", line 10, in chat_room
    chatroom,_= Room.objects.get_or_create(room_name=room_name)
               ^^^^^^^^^^^^^^^^^^^^^^^^^^^^^^^^^^^^^
  File "C:\Users\Administrator\dl\.venv\Lib\site-packages\django\db\models\manager.py", line 87, in manager_method
    return getattr(self.get_queryset(), name)(*args, **kwargs)
           ~~~~~~~~~~~~~~~~~~~~~~~~~~~~~~~~~~^^^^^^^^^^^^^^^^^
  File "C:\Users\Administrator\dl\.venv\Lib\site-packages\django\db\models\query.py", line 633, in get
    raise self.model.DoesNotExist(
        "%s matching query does not exist." % self.model._meta.object_name
    )
chat.models.Room.DoesNotExist: Room matching query does not exist.
WARNING 2025-08-24 17:20:24,111 log Not Found: /favicon.ico
WARNING 2025-08-25 07:49:18,990 log Not Found: /chat/room_list/
WARNING 2025-08-25 07:53:02,644 log Not Found: /chat/chat/tttttt/
WARNING 2025-08-25 07:53:21,994 log Not Found: /room/chat/tttttt/
